finally_called_exception_from_catch(volatile unsigned int* thrown, volatile unsigned int* called)
{
    TRY {
    }
    CATCH_ALL {
        if((*thrown) > 0) {
            printf("05: Looping exception\n");
            failed = TRUE;
        } else {
            (*thrown) += 10;
            THROW(BoundsError);
        }
    }
    FINALLY {
        (*called) += 10;
    }
    ENDTRY;
}
